Workbook

Sheet Leads
A1: Company | B1: Trade | C1: City | D1: State | E1: Website | F1: Contact | G1: Title | H1: Email | I1: Phone | J1: Employees | K1: Contactable | L1: Status | M1: Notes | N1: Source Notes | O1: Source | P1: Retrieved | Q1: Source ID
A2: Lehigh HVAC LLC | B2: hvac, furnace repair, heating repair, air conditioning, residential hvac, commercial hvac | C2: Pen Argyl | D2: PA | E2: http://www.lehighhvac.com | I2: +1 484-961-7044 | J2: 1 | K2: =IF(OR(H2<>"",I2<>""),"Yes","No") | L2: New | O2: apollo.io/organizations | P2: 2026-09-19T17:30:01+00:00 | Q2: 614da4054996d900012c34a2
A3: Handyside Plumbing, HVAC & Electrical | B3: service plumbing, service hvac, service electrical, hvac installation, duct cleaning | C3: Goldsboro | D3: PA | E3: http://www.handyside.com | I3: +1 717-938-2521 | J3: 25 | K3: =IF(OR(H3<>"",I3<>""),"Yes","No") | L3: New | O3: apollo.io/organizations | P3: 2026-09-19T17:30:01+00:00 | Q3: 54a1a2bf74686942d363ac03
A4: The Longacre Company | B4: electrical services, plumbing services, hvac, remodeling, kitchen remodeling | C4: Bally | D4: PA | E4: http://www.longacreco.com | I4: +1 610-845-2261 | J4: 17 | K4: =IF(OR(H4<>"",I4<>""),"Yes","No") | L4: New | O4: apollo.io/organizations | P4: 2026-09-19T17:30:01+00:00 | Q4: 54a11bd969702d8ed4256200
A5: Lancaster Plumbing Heating Cooling & Electrical | B5: plumbing, heating, air conditioning, electrical, drain cleaning | C5: East Petersburg | D5: PA | E5: http://www.lph.biz | I5: +1 717-207-9952 | J5: 21 | K5: =IF(OR(H5<>"",I5<>""),"Yes","No") | L5: New | O5: apollo.io/organizations | P5: 2026-09-19T17:30:01+00:00 | Q5: 57c4f7eda6da986aaa172238
A6: Resnick Roofing & Contracting | B6: roofing, siding, gutters, roof repair, roof replacement | C6: Gibsonia | D6: PA | E6: http://www.resnickroof.com | I6: +1 412-307-9809 | J6: 30 | K6: =IF(OR(H6<>"",I6<>""),"Yes","No") | L6: New | O6: apollo.io/organizations | P6: 2026-09-19T17:30:01+00:00 | Q6: 5e5610acf74c260001f7d303
A7: JB Plumbing HVAC Construction | B7: hvac services, plumbing services, home remodeling & renovations, decks & additions | C7: Reading | D7: PA | E7: http://www.jbplumbinghvac.com | I7: +1 610-621-3452 | J7: 1 | K7: =IF(OR(H7<>"",I7<>""),"Yes","No") | L7: New | O7: apollo.io/organizations | P7: 2026-09-19T17:30:01+00:00 | Q7: 5fd85c81c0cf980001cf01c9
A8: Madison Concrete Construction | B8: commercial concrete construction, concrete pumping, slabs on grade, structural concrete | C8: Malvern | D8: PA | E8: http://www.madisonconcrete.com | I8: +1 610-695-8800 | J8: 42 | K8: =IF(OR(H8<>"",I8<>""),"Yes","No") | L8: New | O8: apollo.io/organizations | P8: 2026-09-19T17:30:01+00:00 | Q8: 62eb4841004d24000161dae3
A9: Croom Concrete | B9: precast concrete, cattle slats, box culverts, septic tanks | D9: PA | E9: http://www.croomconcrete.com | I9: +44 739 853 4484 | J9: 46 | K9: =IF(OR(H9<>"",I9<>""),"Yes","No") | L9: New | N9: Apollo reports state=Pennsylvania but raw_address and +44 phone indicate Limerick, Ireland. Geography filter will pass this incorrectly. | O9: apollo.io/organizations | P9: 2026-09-19T17:30:01+00:00 | Q9: 556d54fb7369641266ffeb00
A10: BLM Construction & Remodeling, LLC | B10: remodeling, roofing, painting, concrete, kitchen, bathroom | C10: York | D10: PA | E10: http://www.blmconstruction.net | I10: +1 717-650-1472 | J10: 21 | K10: =IF(OR(H10<>"",I10<>""),"Yes","No") | L10: New | O10: apollo.io/organizations | P10: 2026-09-19T17:30:01+00:00 | Q10: 5f49df2bf15fd000014be47f
A11: Voomi Supply | B11: hvac parts, hvac supplies, wholesale trade, e-commerce | C11: Philadelphia | D11: PA | E11: http://www.voomisupply.com | I11: +1 215-326-9845 | J11: 41 | K11: =IF(OR(H11<>"",I11<>""),"Yes","No") | L11: New | N11: Distributor, not a contractor. | O11: apollo.io/organizations | P11: 2026-09-19T17:30:01+00:00 | Q11: 61b6f541117cfd00a48bc4c2
A12: Moser Roofing Solutions, LLC | B12: commercial roofing, roof restoration, roof repair, roof replacement, metal roofing | C12: Lancaster | D12: PA | E12: http://www.moserroofingsolutions.com | I12: +1 717-690-2581 | J12: 41 | K12: =IF(OR(H12<>"",I12<>""),"Yes","No") | L12: New | O12: apollo.io/organizations | P12: 2026-09-19T17:30:01+00:00 | Q12: 5f4827ea7a32a000011996c7
A13: American Construction & Concrete | B13: concrete, painting, roofing, general contracting, commercial construction | C13: Mount Joy | D13: PA | E13: http://www.americancandc.com | I13: +1 717-458-1976 | J13: 32 | K13: =IF(OR(H13<>"",I13<>""),"Yes","No") | L13: New | O13: apollo.io/organizations | P13: 2026-09-19T17:30:01+00:00 | Q13: 6437c5a0b0185e01b39eb62e
A14: McHales Inc. | B14: plumbing, hvac, electrical, remodeling, home services | C14: Levittown | D14: PA | E14: http://www.mchales.net | I14: +1 215-443-3333 | J14: 13 | K14: =IF(OR(H14<>"",I14<>""),"Yes","No") | L14: New | O14: apollo.io/organizations | P14: 2026-09-19T17:30:01+00:00 | Q14: 636ce79ea839d300a34c2beb
A15: Modern Plumbing & Heating | B15: plumbing services, hvac, electrical, drain cleaning, water heater repair | C15: Macungie | D15: PA | E15: http://www.modernplumbingpa.com | I15: +1 610-435-2081 | J15: 4 | K15: =IF(OR(H15<>"",I15<>""),"Yes","No") | L15: New | O15: apollo.io/organizations | P15: 2026-09-19T17:30:01+00:00 | Q15: 65e2e8d09db56401c6b45eea
A16: Gillece | B16: plumbing services, heating services, cooling services, electrical services | C16: Bridgeville | D16: PA | I16: +1 412-888-0010 | J16: 31 | K16: =IF(OR(H16<>"",I16<>""),"Yes","No") | L16: New | N16: Queried gillece.com; Apollo matched a different org record (id 54a1364b..., no primary_domain) than the lookup result (id 6336c0bd..., 'Gillece Services'). | O16: apollo.io/organizations | P16: 2026-09-19T17:30:01+00:00 | Q16: 54a1364b69702d46f0051401
A17: FORTA Concrete Fiber | B17: fiber reinforcement, concrete reinforcement, concrete fibers | C17: Grove City | D17: PA | E17: http://www.fortacorp.com | I17: +1 724-458-5221 | J17: 44 | K17: =IF(OR(H17<>"",I17<>""),"Yes","No") | L17: New | N17: Manufacturer of concrete fiber, not a contractor. Owned by The Heritage Group. | O17: apollo.io/organizations | P17: 2026-09-19T17:30:01+00:00 | Q17: 54a1289b69702d9548e62201
A18: Gray Concrete 2 Go | B18: concrete supply, concrete delivery, decorative concrete | C18: Dover | D18: PA | E18: http://www.grayconcrete2go.com | I18: +1 717-577-3520 | J18: 3 | K18: =IF(OR(H18<>"",I18<>""),"Yes","No") | L18: New | N18: Concrete supplier. Owned by Gray Concrete Construction. | O18: apollo.io/organizations | P18: 2026-09-19T17:30:01+00:00 | Q18: 6726fb136893d600010ae1c5
A19: Christian Home Services Heating, Cooling, Plumbing & Electrical | B19: hvac, plumbing, electrical, furnace repair, air conditioning | C19: Southampton | D19: PA | E19: http://www.christianhvac.com | I19: +1 215-372-8636 | J19: 33 | K19: =IF(OR(H19<>"",I19<>""),"Yes","No") | L19: New | O19: apollo.io/organizations | P19: 2026-09-19T17:30:01+00:00 | Q19: 54a11cf469702d9d7e62e300
A20: GEN3 Electric & HVAC | B20: electrical services, hvac, electrician, panel upgrades, furnace repair | C20: Philadelphia | D20: PA | E20: http://www.generation3electric.com | I20: +1 215-512-4102 | J20: 50 | K20: =IF(OR(H20<>"",I20<>""),"Yes","No") | L20: New | O20: apollo.io/organizations | P20: 2026-09-19T17:30:01+00:00 | Q20: 556dc3937369641258da8301
A21: American Remodeling Enterprises Inc. | B21: roofing, siding, windows, remodeling, bathroom remodeling | C21: Schuylkill Haven | D21: PA | E21: http://www.americanremodeling.net | I21: +1 888-739-7339 | J21: 29 | K21: =IF(OR(H21<>"",I21<>""),"Yes","No") | L21: New | O21: apollo.io/organizations | P21: 2026-09-19T17:30:01+00:00 | Q21: 6129a94cc7406400016e8192
A22: Wm. Henderson Plumbing Heating and Cooling | B22: plumbing, hvac, electrical, drain cleaning, water heaters | C22: Broomall | D22: PA | E22: http://www.wmhendersoninc.com | I22: +1 610-544-7999 | J22: 35 | K22: =IF(OR(H22<>"",I22<>""),"Yes","No") | L22: New | O22: apollo.io/organizations | P22: 2026-09-19T17:30:01+00:00 | Q22: 5d096a28f651257f55823650
A23: Howard Concrete Pumping Company, Inc. | B23: concrete pumping, mine grouting, shotcrete walls, micropiles | C23: Canonsburg | D23: PA | E23: http://www.howardconcretepumping.com | I23: +1 412-257-1800 | J23: 43 | K23: =IF(OR(H23<>"",I23<>""),"Yes","No") | L23: New | O23: apollo.io/organizations | P23: 2026-09-19T17:30:01+00:00 | Q23: 55ef0a72f3e5bb285000281c
A24: Thermotech, Inc. | B24: heating, air conditioning, refrigeration, electrical, plumbing | C24: Camp Hill | D24: PA | E24: http://www.thermotechhbg.com | I24: +1 717-234-4500 | J24: 19 | K24: =IF(OR(H24<>"",I24<>""),"Yes","No") | L24: New | N24: Apollo's short_description describes a Minnesota injection-molding firm, not this PA HVAC/refrigeration contractor. Description field is unreliable for this record. | O24: apollo.io/organizations | P24: 2026-09-19T17:30:01+00:00 | Q24: 5c1ec7d4f651259b6e1f4b5b
A25: SJ Remodeling Co. | B25: remodeling, flooring, roofing, painting, drywall, landscaping | C25: Carlisle | D25: PA | E25: http://www.sjremodelingco.com | I25: +1 717-305-2749 | J25: 5 | K25: =IF(OR(H25<>"",I25<>""),"Yes","No") | L25: New | O25: apollo.io/organizations | P25: 2026-09-19T17:30:01+00:00 | Q25: 664c381c0302770001727f9d
A26: Essig Plumbing & Heating | B26: plumbing, heating, air conditioning, drain cleaning, heat pumps | C26: Reading | D26: PA | E26: http://www.makeitessig.com | I26: +1 610-557-3302 | J26: 35 | K26: =IF(OR(H26<>"",I26<>""),"Yes","No") | L26: New | O26: apollo.io/organizations | P26: 2026-09-19T17:30:01+00:00 | Q26: 56de964bf3e5bb706e000fe4
A27: Restano Heating, Cooling, Plumbing & Electrical | B27: hvac, plumbing, furnace repair, air conditioning repair | C27: Plum | D27: PA | E27: http://www.restano.com | I27: +1 412-528-1018 | J27: 17 | K27: =IF(OR(H27<>"",I27<>""),"Yes","No") | L27: New | O27: apollo.io/organizations | P27: 2026-09-19T17:30:01+00:00 | Q27: 5f485faab495f8000111eb37
A28: SelectPro LLC | B28: hvac, plumbing, roofing, siding, painting, remodeling | C28: Upper Darby | D28: PA | E28: http://www.selectprollc.com | I28: +1 610-880-8980 | J28: 2 | K28: =IF(OR(H28<>"",I28<>""),"Yes","No") | L28: New | O28: apollo.io/organizations | P28: 2026-09-19T17:30:01+00:00 | Q28: 56e29dfef3e5bb18dd00148d
A29: iFixit General Contractor | B29: carpentry, plumbing, electrical, roofing, landscaping, painting services | C29: Langhorne | D29: PA | E29: http://www.ifixith.com | I29: +1 267-214-0944 | J29: 4 | K29: =IF(OR(H29<>"",I29<>""),"Yes","No") | L29: New | O29: apollo.io/organizations | P29: 2026-09-19T17:30:01+00:00 | Q29: 5da6eb5884afb000019f805d
A30: Rapid Air HVAC | B30: hvac, heating, air conditioning, furnace repair, boiler repair | C30: Pottstown | D30: PA | E30: http://www.rapidairhvac.com | I30: +1 484-763-2704 | J30: 9 | K30: =IF(OR(H30<>"",I30<>""),"Yes","No") | L30: New | O30: apollo.io/organizations | P30: 2026-09-19T17:30:01+00:00 | Q30: 67284c4962f46c0001d23e6e
A31: Ames Construction, Inc. | B31: general contractor, plumbing, hvac, commercial construction | C31: Ephrata | D31: PA | E31: http://www.amesconstructioninc.com | I31: +1 717-733-4141 | J31: 34 | K31: =IF(OR(H31<>"",I31<>""),"Yes","No") | L31: New | O31: apollo.io/organizations | P31: 2026-09-19T17:30:01+00:00 | Q31: 55eb8c91f3e5bb13700002e4
A32: Heidler Roofing, LLC | B32: roofing, commercial roofing, residential roofing, metal roofing, slate | C32: York | D32: PA | E32: http://www.heidlerroofing.com | I32: +1 717-792-3549 | J32: 46 | K32: =IF(OR(H32<>"",I32<>""),"Yes","No") | L32: New | O32: apollo.io/organizations | P32: 2026-09-19T17:30:01+00:00 | Q32: 54a1d1b674686945fa9b7e13
A33: F5 Facility Services | B33: plumbing service, hvac service, painting, carpentry, concrete work, electrical service work | C33: McKees Rocks | D33: PA | E33: http://www.f5svcs.com | I33: +1 412-921-5555 | J33: 22 | K33: =IF(OR(H33<>"",I33<>""),"Yes","No") | L33: New | O33: apollo.io/organizations | P33: 2026-09-19T17:30:01+00:00 | Q33: 5da361a4e53eb80001767204
A34: Mattioni Plumbing, Heating & Cooling | B34: plumbing, hvac, heating, cooling, water heater services | C34: Downingtown | D34: PA | E34: http://www.callmattioni.com | I34: +1 610-400-8510 | J34: 44 | K34: =IF(OR(H34<>"",I34<>""),"Yes","No") | L34: New | O34: apollo.io/organizations | P34: 2026-09-19T17:30:01+00:00 | Q34: 5a9e305fa6da98d96643c97b
A35: Russell Roofing & Exteriors | B35: roofing, gutters, siding, windows, masonry, slate | C35: Oreland | D35: PA | E35: http://www.russellroofing.com | I35: +1 888-567-7663 | J35: 34 | K35: =IF(OR(H35<>"",I35<>""),"Yes","No") | L35: New | O35: apollo.io/organizations | P35: 2026-09-19T17:30:01+00:00 | Q35: 54a138e269702d2bfdc91300
A36: Home Exchange PA | B36: carpentry services, lawn care, remodeling, plumbing services, roofing, painting | C36: Philadelphia | D36: PA | E36: http://www.homexchangepa.com | I36: +1 215-966-1660 | J36: 6 | K36: =IF(OR(H36<>"",I36<>""),"Yes","No") | L36: New | O36: apollo.io/organizations | P36: 2026-09-19T17:30:01+00:00 | Q36: 5fcb2475439c2e00016b5ac4
... A42: Eastern Roofing Systems, Inc. | B42: commercial roofing, metal roofs, flat roofing, roof maintenance | C42: Jessup | D42: PA | E42: http://www.easternroofingsystems.com | I42: +1 570-383-1818 | J42: 26 | K42: =IF(OR(H42<>"",I42<>""),"Yes","No") | L42: New | O42: apollo.io/organizations | P42: 2026-09-19T17:30:01+00:00 | Q42: 54a19a07746869586086e200
A43: Gray Concrete Construction | B43: concrete construction, decorative concrete, retaining walls, concrete repair | C43: Dover | D43: PA | E43: http://www.grayconcreteconstruction.com | I43: +1 717-577-3520 | J43: 3 | K43: =IF(OR(H43<>"",I43<>""),"Yes","No") | L43: New | N43: Shares phone with Gray Concrete 2 Go (sister company, same number). | O43: apollo.io/organizations | P43: 2026-09-19T17:30:01+00:00 | Q43: 5500c2ba7369646159214300
A44: James Brown Plumbing Heating & Air Conditioning, LLC | B44: plumbing, heating, air conditioning, geothermal, radiant heat, landscaping | C44: West Chester | D44: PA | E44: http://www.jamesbrownphac.com | I44: +1 610-873-0622 | J44: 8 | K44: =IF(OR(H44<>"",I44<>""),"Yes","No") | L44: New | O44: apollo.io/organizations | P44: 2026-09-19T17:30:01+00:00 | Q44: 54a1c0f974686945fa29ff0d
A45: Snyder's Plumbing Inc. | B45: residential plumbing, residential hvac, remodeling, water treatment | C45: Lancaster | D45: PA | E45: http://www.snydersplumbing.com | I45: +1 717-492-9128 | J45: 6 | K45: =IF(OR(H45<>"",I45<>""),"Yes","No") | L45: New | O45: apollo.io/organizations | P45: 2026-09-19T17:30:01+00:00 | Q45: 55f432b7f3e5bb1e190069c8
...

Sheet Rejected
A1: Company | B1: Trade | C1: City | D1: State | E1: Email | F1: Phone | G1: Rejected for
A2: United Employment Group, Inc. | B2: executive search, construction staffing, recruitment services | C2: Allentown | D2: PA | F2: +1 610-351-8070 | G2: trade executive search, construction staffing, recruitment services not in target list
A3: Veteran Forged Solutions | B3: general construction renovations, drywall, painting, roofing, light carpentry | C3: West Chester | D3: PA | G3: no email or phone
A4: JR Contractor LLC | B4: renovations, drywall, painting, roofing framing, decks | C4: Coatesville | D4: PA | G4: no email or phone
A5: Mesta Electronics, LLC | B5: power quality, transformers, harmonic filters | C5: North Huntingdon | D5: PA | F5: +1 412-754-3000 | G5: trade power quality, transformers, harmonic filters not in target list
A6: Focal Point Remodeling | B6: bathroom remodel, kitchen remodel, window replacement, roofing | C6: Harrisburg | D6: PA | G6: no email or phone
A7: Advanced Construction Robotics | B7: construction, robotics, rebar installation, bridge construction | C7: Pittsburgh | D7: PA | F7: +1 412-756-3360 | G7: trade construction, robotics, rebar installation, bridge construction not in target list

Sheet Summary
A1: Lead list summary
A3: Qualified leads | B3: =COUNTA(Leads!A2:A90) | C3: Rows on the Leads tab.
A4: With email | B4: =COUNTIF(Leads!H2:H90,"?*") | C4: Non-blank Email cells.
A5: With phone | B5: =COUNTIF(Leads!I2:I90,"?*") | C5: Non-blank Phone cells.
A6: Contactable | B6: =COUNTIF(Leads!K2:K90,"Yes") | C6: Either an email or a phone number.
A7: Rejected | B7: 6 | C7: See the Rejected tab for the reason on each.
A10: Pipeline
A11: New | B11: =COUNTIF(Leads!L2:L90,"New")
A12: Contacted | B12: =COUNTIF(Leads!L2:L90,"Contacted")
A13: Replied | B13: =COUNTIF(Leads!L2:L90,"Replied")
A14: Meeting | B14: =COUNTIF(Leads!L2:L90,"Meeting")
A15: Won | B15: =COUNTIF(Leads!L2:L90,"Won")
A16: Dead | B16: =COUNTIF(Leads!L2:L90,"Dead")
A19: How to use this
A20: Yellow cells are yours to edit — column L (Status) and column M (Notes) on the Leads tab.
A21: Status accepts: New, Contacted, Replied, Meeting, Won, Dead. The Pipeline counts above follow what you type.
A22: Contactable (column K) is a formula. Fill in a missing phone or email and it updates itself.
A23: Everything else came from the source and is overwritten on the next export.
A24: Filters applied — states: PA; 8 trades; contactable only
